mkdir failed on directory /var/lib/samba/lock/msg.lock: Permission denied
[2024-07-14 15:27:45,043] torch.distributed.run: [WARNING] master_addr is only used for static rdzv_backend and when rdzv_endpoint is not specified.
[2024-07-14 15:27:45,044] torch.distributed.run: [WARNING] 
[2024-07-14 15:27:45,044] torch.distributed.run: [WARNING] *****************************************
[2024-07-14 15:27:45,044] torch.distributed.run: [WARNING] Setting OMP_NUM_THREADS environment variable for each process to be 1 in default, to avoid your system being overloaded, please further tune the variable for optimal performance in your application as needed. 
[2024-07-14 15:27:45,044] torch.distributed.run: [WARNING] *****************************************
Traceback (most recent call last):
Traceback (most recent call last):
  File "/public/home/acr0vd9ik6/project/DiT/fast-DiT/save_train_set_2_npz.py", line 147, in <module>
  File "/public/home/acr0vd9ik6/project/DiT/fast-DiT/save_train_set_2_npz.py", line 147, in <module>
        npz_file = create_npz_from_train_folder_3('/public/home/acr0vd9ik6/project/DiT/train')npz_file = create_npz_from_train_folder_3('/public/home/acr0vd9ik6/project/DiT/train')

NameErrorNameError: : name 'create_npz_from_train_folder_3' is not definedname 'create_npz_from_train_folder_3' is not defined. Did you mean: '. Did you mean: 'create_npz_from_train_folder_2create_npz_from_train_folder_2'?'?

Traceback (most recent call last):
Traceback (most recent call last):
  File "/public/home/acr0vd9ik6/project/DiT/fast-DiT/save_train_set_2_npz.py", line 147, in <module>
  File "/public/home/acr0vd9ik6/project/DiT/fast-DiT/save_train_set_2_npz.py", line 147, in <module>
        npz_file = create_npz_from_train_folder_3('/public/home/acr0vd9ik6/project/DiT/train')npz_file = create_npz_from_train_folder_3('/public/home/acr0vd9ik6/project/DiT/train')

NameErrorNameError: : name 'create_npz_from_train_folder_3' is not definedname 'create_npz_from_train_folder_3' is not defined. Did you mean: '. Did you mean: 'create_npz_from_train_folder_2create_npz_from_train_folder_2'?'?

[2024-07-14 15:27:50,326] torch.distributed.elastic.multiprocessing.api: [ERROR] failed (exitcode: 1) local_rank: 0 (pid: 639) of binary: /public/home/acr0vd9ik6/miniconda3/envs/torch-2.1.0.dtk-24.04.cp310/bin/python
Traceback (most recent call last):
  File "/public/home/acr0vd9ik6/miniconda3/envs/torch-2.1.0.dtk-24.04.cp310/bin/torchrun", line 8, in <module>
    sys.exit(main())
  File "/public/home/acr0vd9ik6/miniconda3/envs/torch-2.1.0.dtk-24.04.cp310/lib/python3.10/site-packages/torch/distributed/elastic/multiprocessing/errors/__init__.py", line 346, in wrapper
    return f(*args, **kwargs)
  File "/public/home/acr0vd9ik6/miniconda3/envs/torch-2.1.0.dtk-24.04.cp310/lib/python3.10/site-packages/torch/distributed/run.py", line 806, in main
    run(args)
  File "/public/home/acr0vd9ik6/miniconda3/envs/torch-2.1.0.dtk-24.04.cp310/lib/python3.10/site-packages/torch/distributed/run.py", line 797, in run
    elastic_launch(
  File "/public/home/acr0vd9ik6/miniconda3/envs/torch-2.1.0.dtk-24.04.cp310/lib/python3.10/site-packages/torch/distributed/launcher/api.py", line 134, in __call__
    return launch_agent(self._config, self._entrypoint, list(args))
  File "/public/home/acr0vd9ik6/miniconda3/envs/torch-2.1.0.dtk-24.04.cp310/lib/python3.10/site-packages/torch/distributed/launcher/api.py", line 264, in launch_agent
    raise ChildFailedError(
torch.distributed.elastic.multiprocessing.errors.ChildFailedError: 
============================================================
save_train_set_2_npz.py FAILED
------------------------------------------------------------
Failures:
[1]:
  time      : 2024-07-14_15:27:50
  host      : e10r3n13
  rank      : 1 (local_rank: 1)
  exitcode  : 1 (pid: 640)
  error_file: <N/A>
  traceback : To enable traceback see: https://pytorch.org/docs/stable/elastic/errors.html
[2]:
  time      : 2024-07-14_15:27:50
  host      : e10r3n13
  rank      : 2 (local_rank: 2)
  exitcode  : 1 (pid: 641)
  error_file: <N/A>
  traceback : To enable traceback see: https://pytorch.org/docs/stable/elastic/errors.html
[3]:
  time      : 2024-07-14_15:27:50
  host      : e10r3n13
  rank      : 3 (local_rank: 3)
  exitcode  : 1 (pid: 642)
  error_file: <N/A>
  traceback : To enable traceback see: https://pytorch.org/docs/stable/elastic/errors.html
------------------------------------------------------------
Root Cause (first observed failure):
[0]:
  time      : 2024-07-14_15:27:50
  host      : e10r3n13
  rank      : 0 (local_rank: 0)
  exitcode  : 1 (pid: 639)
  error_file: <N/A>
  traceback : To enable traceback see: https://pytorch.org/docs/stable/elastic/errors.html
============================================================
